Workbook

Sheet Sheet3
A3: Row Labels | B3: Average of Resident_Population (R) | C3: Average of Displaced_Population (D) | D3: Average of Heterogeneity (H) | E3: Average of Displacement_Ratio (S = D/R) | F3: Average of Demographic_Factor (DF = S*H)
A4: Akkar | B4: 2866.2616 | C4: 91.854651 | D4: 0.20116408 | E4: 0.043141376 | F4: 0.0087632853
A5: Aley | B5: 3735.869 | C5: 1632.1071 | D5: 0.30162654 | E5: 0.46151216 | F5: 0.14564807
A6: Baabda | B6: 9389.1803 | C6: 580.70492 | D6: 0.34485306 | E6: 0.35540818 | F6: 0.0940857
A7: Baalbek | B7: 3730.2574 | C7: 103.35644 | D7: 0.1843537 | E7: 0.074708806 | F7: 0.013789887
A8: Bcharre | B8: 962 | C8: 20.130435 | D8: 0.14893639 | E8: 0.039998859 | F8: 0.0085150869
A9: Beirut | B9: 23308.462 | C9: 12625.923 | D9: 0.6131932 | E9: 0.97586843 | F9: 0.59471623
A10: Bent Jbeil | B10: 1756.7105 | C10: 2.6578947 | D10: 0.09971194 | E10: 0.00093620476 | F10: 0.0001876055
A11: Chouf | B11: 2628.7778 | C11: 1143.2323 | D11: 0.26185194 | E11: 0.31107466 | F11: 0.090263516
A12: El Batroun | B12: 912.22535 | C12: 103.04225 | D12: 0.2187409 | E12: 0.14456845 | F12: 0.030107366
A13: El Hermel | B13: 4051.2857 | C13: 117.78571 | D13: 0.22132985 | E13: 0.1090522 | F13: 0.014322792
A14: El Koura | B14: 2139.575 | C14: 126.45 | D14: 0.29229832 | E14: 0.20933588 | F14: 0.061089539
A15: El Meten | B15: 4860.8247 | C15: 200.46392 | D15: 0.38250474 | E15: 0.05198022 | F15: 0.019314589
... A29: Zgharta | B29: 1714.3269 | C29: 68.557692 | D29: 0.20934753 | E29: 0.046930621 | F29: 0.010375918
A30: (blank)
A31: Grand Total | B31: 3302.5101 | C31: 422.66073 | D31: 0.23995882 | E31: 0.2524536 | F31: 0.061359101

Sheet Master Sheet
A1: Status | B1: Updated Nmes | C1: District | D1: District_Cleaned | E1: Governorate | F1: ACS Code | G1: Resident_Population (R) | H1: Displaced_Population (D) | I1: Heterogeneity (H) | J1: Displacement_Ratio (S = D/R) | K1: Demographic_Factor (DF = S*H)
A2: Actual | B2: عين المريسه | C2: بيروت | D2: Beirut | E2: بيروت | F2: 10110 | G2: 4550 | H2: 28800 | I2: 0.65991017 | J2: =IF(G2=0,0,H2/G2) -> 6.3296703 | K2: =J2*I2 -> 4.1770138 | M2: Actual | N2: =COUNTIF(A:A,M2) -> 1216
A3: Actual | B3: رأس بيروت | C3: بيروت | D3: Beirut | E3: بيروت | F3: 10150 | G3: 37706 | H3: 39690 | I3: 0.53190599 | J3: =IF(G3=0,0,H3/G3) -> 1.0526176 | K3: =J3*I3 -> 0.55989361 | M3: Predicted | N3: =COUNTIF(A:A,M3) -> 411
A4: Actual | B4: مصيطبة | C4: بيروت | D4: Beirut | E4: بيروت | F4: 10210 | G4: 66330 | H4: 64913 | I4: 0.59862798 | J4: =IF(G4=0,0,H4/G4) -> 0.97863712 | K4: =J4*I4 -> 0.58583956 | P4: {=_xlfn.UNIQUE(D2:D1628)} -> Beirut
A5: Actual | B5: مينا الحصن | C5: بيروت | D5: Beirut | E5: بيروت | F5: 10250 | G5: 1524 | H5: 0 | I5: 0.83693546 | J5: =IF(G5=0,0,H5/G5) -> 0 | K5: =J5*I5 -> 0 | P5: Baabda
A6: Actual | B6: المزرعة | C6: بيروت | D6: Beirut | E6: بيروت | F6: 10310 | G6: 88885 | H6: 16650 | I6: 0.27341794 | J6: =IF(G6=0,0,H6/G6) -> 0.1873207 | K6: =J6*I6 -> 0.051216838 | P6: Aley
A7: Actual | B7: باشورة | C7: بيروت | D7: Beirut | E7: بيروت | F7: 10350 | G7: 16218 | H7: 1851 | I7: 0.58627379 | J7: =IF(G7=0,0,H7/G7) -> 0.11413245 | K7: =J7*I7 -> 0.066912862 | P7: Baalbek
A8: Actual | B8: زقاق البلاط | C8: بيروت | D8: Beirut | E8: بيروت | F8: 10410 | G8: 10658 | H8: 1350 | I8: 0.56572695 | J8: =IF(G8=0,0,H8/G8) -> 0.12666542 | K8: =J8*I8 -> 0.071658039 | P8: Akkar
A9: Actual | B9: مرفأ | C9: بيروت | D9: Beirut | E9: بيروت | F9: 10450 | G9: 151 | H9: 450 | I9: 0.54555407 | J9: =IF(G9=0,0,H9/G9) -> 2.9801325 | K9: =J9*I9 -> 1.6258234 | P9: Hasbaya
A10: Actual | B10: صيفي | C10: بيروت | D10: Beirut | E10: بيروت | F10: 10510 | G10: 2152 | H10: 203 | I10: 0.80288475 | J10: =IF(G10=0,0,H10/G10) -> 0.094330855 | K10: =J10*I10 -> 0.075736805 | P10: Kesrwane
A11: Actual | B11: رميل | C11: بيروت | D11: Beirut | E11: بيروت | F11: 10550 | G11: 21978 | H11: 1238 | I11: 0.80288475 | J11: =IF(G11=0,0,H11/G11) -> 0.056329056 | K11: =J11*I11 -> 0.04522574 | P11: Jezzine
A12: Actual | B12: مدور | C12: بيروت | D12: Beirut | E12: بيروت | F12: 10610 | G12: 4151 | H12: 1890 | I12: 0.677964 | J12: =IF(G12=0,0,H12/G12) -> 0.45531197 | K12: =J12*I12 -> 0.30868513 | P12: Rachaya
A13: Actual | B13: الاشرفية | C13: بيروت | D13: Beirut | E13: بيروت | F13: 10650 | G13: 48435 | H13: 7057 | I13: 0.85764884 | J13: =IF(G13=0,0,H13/G13) -> 0.14570042 | K13: =J13*I13 -> 0.1249598 | P13: Zahle
A14: Actual | B14: شياح | C14: بعبدا | D14: Baabda | E14: جبل لبنان | F14: 21111 | G14: 239203 | H14: 10240 | I14: 0.61645564 | J14: =IF(G14=0,0,H14/G14) -> 0.042808828 | K14: =J14*I14 -> 0.026389743 | P14: Jbeil
A15: Actual | B15: حارة حريك | C15: بعبدا | D15: Baabda | E15: جبل لبنان | F15: 21144 | G15: 62844 | H15: 0 | I15: 0.63399263 | J15: =IF(G15=0,0,H15/G15) -> 0 | K15: =J15*I15 -> 0 | P15: Marjaayoun
A16: Actual | B16: ليلكي | C16: بعبدا | D16: Baabda | E16: جبل لبنان | F16: 21166 | G16: 11078 | H16: 0 | I16: 0.35640496 | J16: =IF(G16=0,0,H16/G16) -> 0 | K16: =J16*I16 -> 0 | P16: Sour
... A29: Actual | B29: عين موفق | C29: بعبدا | D29: Baabda | E29: جبل لبنان | F29: 21314 | G29: 15 | H29: 76 | I29: 0.25378667 | J29: =IF(G29=0,0,H29/G29) -> 5.0666667 | K29: =J29*I29 -> 1.2858525 | P29: Bcharre
A30: Actual | B30: رويسة البلوط | C30: بعبدا | D30: Baabda | E30: جبل لبنان | F30: 21317 | G30: 822 | H30: 820 | I30: 0.037565512 | J30: =IF(G30=0,0,H30/G30) -> 0.99756691 | K30: =J30*I30 -> 0.037474112
A31: Actual | B31: هلالية | C31: بعبدا | D31: Baabda | E31: جبل لبنان | F31: 21324 | G31: 375 | H31: 282 | I31: 0.028889961 | J31: =IF(G31=0,0,H31/G31) -> 0.752 | K31: =J31*I31 -> 0.021725251
A32: Actual | B32: حارة حمزة | C32: بعبدا | D32: Baabda | E32: جبل لبنان | F32: 21327 | G32: 27 | H32: 0 | I32: 0.1882553 | J32: =IF(G32=0,0,H32/G32) -> 0 | K32: =J32*I32 -> 0
A33: Actual | B33: قتالة | C33: بعبدا | D33: Baabda | E33: جبل لبنان | F33: 21331 | G33: 0 | H33: 0 | I33: 0.56210652 | J33: =IF(G33=0,0,H33/G33) -> 0 | K33: =J33*I33 -> 0
A34: Actual | B34: راس الحرف | C34: بعبدا | D34: Baabda | E34: جبل لبنان | F34: 21334 | G34: 68 | H34: 160 | I34: 0.22172566 | J34: =IF(G34=0,0,H34/G34) -> 2.3529412 | K34: =J34*I34 -> 0.52170744
A35: Actual | B35: دير خونة | C35: بعبدا | D35: Baabda | E35: جبل لبنان | F35: 21337 | G35: 17 | H35: 0 | I35: 0 | J35: =IF(G35=0,0,H35/G35) -> 0 | K35: =J35*I35 -> 0
A36: Actual | B36: عبادية | C36: بعبدا | D36: Baabda | E36: جبل لبنان | F36: 21341 | G36: 3591 | H36: 1410 | I36: 0.60684416 | J36: =IF(G36=0,0,H36/G36) -> 0.39264829 | K36: =J36*I36 -> 0.23827632
A37: Actual | B37: قرية | C37: بعبدا | D37: Baabda | E37: جبل لبنان | F37: 21344 | G37: 687 | H37: 400 | I37: 0.067828095 | J37: =IF(G37=0,0,H37/G37) -> 0.58224163 | K37: =J37*I37 -> 0.039492341
A38: Actual | B38: راس المتن | C38: بعبدا | D38: Baabda | E38: جبل لبنان | F38: 21351 | G38: 4221 | H38: 374 | I38: 0.20356158 | J38: =IF(G38=0,0,H38/G38) -> 0.088604596 | K38: =J38*I38 -> 0.018036492
A39: Actual | B39: شويت | C39: بعبدا | D39: Baabda | E39: جبل لبنان | F39: 21354 | G39: 869 | H39: 450 | I39: 0.57199842 | J39: =IF(G39=0,0,H39/G39) -> 0.51783659 | K39: =J39*I39 -> 0.29620172
A40: Actual | B40: قبيع | C40: بعبدا | D40: Baabda | E40: جبل لبنان | F40: 21357 | G40: 2365 | H40: 1513 | I40: 0.27235634 | J40: =IF(G40=0,0,H40/G40) -> 0.6397463 | K40: =J40*I40 -> 0.17423896
A41: Actual | B41: قرطادة | C41: بعبدا | D41: Baabda | E41: جبل لبنان | F41: 21361 | G41: 123 | H41: 0 | I41: 0.22625346 | J41: =IF(G41=0,0,H41/G41) -> 0 | K41: =J41*I41 -> 0
... A1461: Predicted | B1461: Conflict | C1461: Baalbek | D1461: Baalbek | E1461: Baalbek-El Hermel | F1461: 54003 | G1461: 0 | H1461: 0 | I1461: 0.23104263 | J1461: =IF(G1461=0,0,H1461/G1461) -> 0 | K1461: =J1461*I1461 -> 0
A1462: Predicted | B1462: Conflict | C1462: Baalbek | D1462: Baalbek | E1462: Baalbek-El Hermel | F1462: 0c10 | G1462: 0 | H1462: 0 | I1462: 0.23104263 | J1462: =IF(G1462=0,0,H1462/G1462) -> 0 | K1462: =J1462*I1462 -> 0
A1463: Predicted | B1463: Conflict | C1463: Baalbek | D1463: Baalbek | E1463: Baalbek-El Hermel | F1463: 0c11 | G1463: 0 | H1463: 0 | I1463: 0.23104263 | J1463: =IF(G1463=0,0,H1463/G1463) -> 0 | K1463: =J1463*I1463 -> 0
A1464: Predicted | B1464: Conflict | C1464: Baalbek | D1464: Baalbek | E1464: Baalbek-El Hermel | F1464: 0c2 | G1464: 0 | H1464: 0 | I1464: 0.23104263 | J1464: =IF(G1464=0,0,H1464/G1464) -> 0 | K1464: =J1464*I1464 -> 0
A1465: Predicted | B1465: Conflict | C1465: Baalbek | D1465: Baalbek | E1465: Baalbek-El Hermel | F1465: 0c3 | G1465: 0 | H1465: 0 | I1465: 0.23104263 | J1465: =IF(G1465=0,0,H1465/G1465) -> 0 | K1465: =J1465*I1465 -> 0
A1466: Predicted | B1466: Conflict | C1466: Baalbek | D1466: Baalbek | E1466: Baalbek-El Hermel | F1466: 0c4 | G1466: 0 | H1466: 0 | I1466: 0.23104263 | J1466: =IF(G1466=0,0,H1466/G1466) -> 0 | K1466: =J1466*I1466 -> 0
A1467: Predicted | B1467: Conflict | C1467: Baalbek | D1467: Baalbek | E1467: Baalbek-El Hermel | F1467: 0c5 | G1467: 0 | H1467: 0 | I1467: 0.23104263 | J1467: =IF(G1467=0,0,H1467/G1467) -> 0 | K1467: =J1467*I1467 -> 0
A1468: Predicted | B1468: Conflict | C1468: Baalbek | D1468: Baalbek | E1468: Baalbek-El Hermel | F1468: 0c6 | G1468: 0 | H1468: 0 | I1468: 0.23104263 | J1468: =IF(G1468=0,0,H1468/G1468) -> 0 | K1468: =J1468*I1468 -> 0
A1469: Predicted | B1469: Conflict | C1469: Baalbek | D1469: Baalbek | E1469: Baalbek-El Hermel | F1469: 0c7 | G1469: 0 | H1469: 0 | I1469: 0.23104263 | J1469: =IF(G1469=0,0,H1469/G1469) -> 0 | K1469: =J1469*I1469 -> 0
A1470: Predicted | B1470: Conflict | C1470: Baalbek | D1470: Baalbek | E1470: Baalbek-El Hermel | F1470: 0c8 | G1470: 0 | H1470: 0 | I1470: 0.23104263 | J1470: =IF(G1470=0,0,H1470/G1470) -> 0 | K1470: =J1470*I1470 -> 0
A1471: Predicted | B1471: Conflict | C1471: Baalbek | D1471: Baalbek | E1471: Baalbek-El Hermel | F1471: 0c9 | G1471: 0 | H1471: 0 | I1471: 0.23104263 | J1471: =IF(G1471=0,0,H1471/G1471) -> 0 | K1471: =J1471*I1471 -> 0
...

Sheet DISTRICT
A1: District | B1: ADM2_Name | C1: Resident_Population (R) | D1: Displaced_Population (D) | E1: Heterogeneity (H) | F1: Displacement_Ratio (S = D/R) | G1: Demographic_Factor (DF = S*H)
A2: Akkar | B2: Akkar | C2: 2866.2616 | D2: 91.854651 | E2: 0.20116408 | F2: 0.043141376 | G2: 0.0087632853
A3: Aley | B3: Aley | C3: 3735.869 | D3: 1632.1071 | E3: 0.30162654 | F3: 0.46151216 | G3: 0.14564807
A4: Baabda | B4: Baabda | C4: 9389.1803 | D4: 580.70492 | E4: 0.34485306 | F4: 0.35540818 | G4: 0.0940857
A5: Baalbek | B5: Baalbek | C5: 3730.2574 | D5: 103.35644 | E5: 0.1843537 | F5: 0.074708806 | G5: 0.013789887
A6: Bcharre | B6: Bcharre | C6: 962 | D6: 20.130435 | E6: 0.14893639 | F6: 0.039998859 | G6: 0.0085150869
A7: Beirut | B7: Beyrouth | C7: 23308.462 | D7: 12625.923 | E7: 0.6131932 | F7: 0.97586843 | G7: 0.59471623
A8: Bent Jbeil | B8: Bent Jbail | C8: 1756.7105 | D8: 2.6578947 | E8: 0.09971194 | F8: 0.00093620476 | G8: 0.0001876055
A9: Chouf | B9: Chouf | C9: 2628.7778 | D9: 1143.2323 | E9: 0.26185194 | F9: 0.31107466 | G9: 0.090263516
A10: El Batroun | B10: Batroun | C10: 912.22535 | D10: 103.04225 | E10: 0.2187409 | F10: 0.14456845 | G10: 0.030107366
A11: El Hermel | B11: Hermel | C11: 4051.2857 | D11: 117.78571 | E11: 0.22132985 | F11: 0.1090522 | G11: 0.014322792
A12: El Koura | B12: Koura | C12: 2139.575 | D12: 126.45 | E12: 0.29229832 | F12: 0.20933588 | G12: 0.061089539
A13: El Meten | B13: El Metn | C13: 4860.8247 | D13: 200.46392 | E13: 0.38250474 | F13: 0.05198022 | G13: 0.019314589
... A27: Zgharta | B27: Zgharta | C27: 1714.3269 | D27: 68.557692 | E27: 0.20934753 | F27: 0.046930621 | G27: 0.010375918

Sheet DF_Calculation
A1: Status | B1: Updated Nmes | C1: District | D1: Governorate | E1: ACS Code | F1: Resident_Population (R) | G1: Displaced_Population (D) | H1: Heterogeneity (H) | I1: Displacement_Ratio (S = D/R) | J1: Demographic_Factor (DF = S*H) | K1: Inside CS | N1: =COUNTIF(H:H,"#N/A") -> 0
A2: Actual | B2: عين المريسه | C2: بيروت | D2: بيروت | E2: 10110 | F2: 4550 | H2: 0.65991017 | I2: =IF(F2=0,0,G2/F2) -> 0 | J2: =I2*H2 -> 0 | K2: 1264 | M2: Actual | N2: =COUNTIF(A:A,M2) -> 1216
A3: Actual | B3: رأس بيروت | C3: بيروت | D3: بيروت | E3: 10150 | F3: 37706 | H3: 0.53190599 | K3: 8110 | M3: Predicted | N3: =COUNTIF(A:A,M3) -> 411 | O3: 0 | P3: =COUNTIFS(A:A,M3,F:F,O3) -> 113
A4: Actual | B4: مصيطبة | C4: بيروت | D4: بيروت | E4: 10210 | F4: 66330 | H4: 0.59862798 | K4: 10641 | O4: 1 | P4: =N3-P3 -> 298
A5: Actual | B5: مينا الحصن | C5: بيروت | D5: بيروت | E5: 10250 | F5: 1524 | H5: 0.83693546 | K5: 2366
A6: Actual | B6: المزرعة | C6: بيروت | D6: بيروت | E6: 10310 | F6: 88885 | H6: 0.27341794 | K6: 9377
A7: Actual | B7: باشورة | C7: بيروت | D7: بيروت | E7: 10350 | F7: 16218 | H7: 0.58627379 | K7: 5516
A8: Actual | B8: زقاق البلاط | C8: بيروت | D8: بيروت | E8: 10410 | F8: 10658 | H8: 0.56572695 | K8: 7819
A9: Actual | B9: مرفأ | C9: بيروت | D9: بيروت | E9: 10450 | F9: 151 | H9: 0.54555407 | K9: 0
A10: Actual | B10: صيفي | C10: بيروت | D10: بيروت | E10: 10510 | F10: 2152 | H10: 0.80288475 | K10: 195
A11: Actual | B11: رميل | C11: بيروت | D11: بيروت | E11: 10550 | F11: 21978 | H11: 0.80288475 | K11: 0
A12: Actual | B12: مدور | C12: بيروت | D12: بيروت | E12: 10610 | F12: 4151 | H12: 0.677964 | K12: 940
A13: Actual | B13: الاشرفية | C13: بيروت | D13: بيروت | E13: 10650 | F13: 48435 | H13: 0.85764884 | K13: 431
A14: Actual | B14: شياح | C14: بعبدا | D14: جبل لبنان | E14: 21111 | F14: 239203 | H14: 0.61645564 | K14: 3749
A15: Actual | B15: حارة حريك | C15: بعبدا | D15: جبل لبنان | E15: 21144 | F15: 62844 | H15: 0.63399263 | K15: 0
A16: Actual | B16: ليلكي | C16: بعبدا | D16: جبل لبنان | E16: 21166 | F16: 11078 | H16: 0.35640496 | K16: 0
... A1461: Predicted | B1461: Conflict | C1461: Baalbek | D1461: Baalbek-El Hermel | E1461: 54003 | F1461: 0 | H1461: 0.23104263 | K1461: 0
A1462: Predicted | B1462: Conflict | C1462: Baalbek | D1462: Baalbek-El Hermel | E1462: 0c10 | F1462: 0 | H1462: 0.23104263 | K1462: 0
A1463: Predicted | B1463: Conflict | C1463: Baalbek | D1463: Baalbek-El Hermel | E1463: 0c11 | F1463: 0 | H1463: 0.23104263 | K1463: 0
A1464: Predicted | B1464: Conflict | C1464: Baalbek | D1464: Baalbek-El Hermel | E1464: 0c2 | F1464: 0 | H1464: 0.23104263 | K1464: 0
A1465: Predicted | B1465: Conflict | C1465: Baalbek | D1465: Baalbek-El Hermel | E1465: 0c3 | F1465: 0 | H1465: 0.23104263 | K1465: 0
A1466: Predicted | B1466: Conflict | C1466: Baalbek | D1466: Baalbek-El Hermel | E1466: 0c4 | F1466: 0 | H1466: 0.23104263 | K1466: 0
A1467: Predicted | B1467: Conflict | C1467: Baalbek | D1467: Baalbek-El Hermel | E1467: 0c5 | F1467: 0 | H1467: 0.23104263 | K1467: 0
A1468: Predicted | B1468: Conflict | C1468: Baalbek | D1468: Baalbek-El Hermel | E1468: 0c6 | F1468: 0 | H1468: 0.23104263 | K1468: 0
A1469: Predicted | B1469: Conflict | C1469: Baalbek | D1469: Baalbek-El Hermel | E1469: 0c7 | F1469: 0 | H1469: 0.23104263 | K1469: 0
A1470: Predicted | B1470: Conflict | C1470: Baalbek | D1470: Baalbek-El Hermel | E1470: 0c8 | F1470: 0 | H1470: 0.23104263 | K1470: 0
A1471: Predicted | B1471: Conflict | C1471: Baalbek | D1471: Baalbek-El Hermel | E1471: 0c9 | F1471: 0 | H1471: 0.23104263 | K1471: 0
A1472: Predicted | B1472: Ouadi El-Aaoss | C1472: Baalbek | D1472: Baalbek-El Hermel | E1472: 54183 | F1472: 0 | H1472: 0.23104263 | K1472: 0
A1473: Predicted | B1473: Slouqi | C1473: Baalbek | D1473: Baalbek-El Hermel | E1473: 53423 | F1473: 17 | H1473: 0.23108853 | K1473: 0
A1474: Predicted | B1474: Mchaa Ej-Jibbe | C1474: Bcharre | D1474: North | E1474: 36110 | F1474: 0 | H1474: 0.23104263 | K1474: 0
A1475: Predicted | B1475: Qatmoun | C1475: Bent Jbeil | D1475: El Nabatieh | E1475: 72175 | F1475: 0 | H1475: 0.23104263 | K1475: 0
A1476: Predicted | B1476: Salhani | C1476: Bent Jbeil | D1476: El Nabatieh | E1476: 72135 | F1476: 0 | H1476: 0.23104263 | K1476: 0
A1477: Predicted | B1477: Chmaarine | C1477: Chouf | D1477: Mount Lebanon | E1477: 23275 | F1477: 0 | H1477: 0.23104263 | K1477: 0
A1478: Predicted | B1478: Conflict | C1478: Chouf | D1478: Mount Lebanon | E1478: 23001 | F1478: 0 | H1478: 0.23104263 | K1478: 0
A1479: Predicted | B1479: Conflict | C1479: Chouf | D1479: Mount Lebanon | E1479: 23002 | F1479: 0 | H1479: 0.23104263 | K1479: 0
A1480: Predicted | B1480: Conflict | C1480: Chouf | D1480: Mount Lebanon | E1480: 23003 | F1480: 0 | H1480: 0.23104263 | K1480: 0
A1481: Predicted | B1481: Conflict | C1481: Chouf | D1481: Mount Lebanon | E1481: 23004 | F1481: 0 | H1481: 0.23104263 | K1481: 0
A1482: Predicted | B1482: Conflict | C1482: Chouf | D1482: Mount Lebanon | E1482: 23005 | F1482: 0 | H1482: 0.23104263 | K1482: 0
A1483: Predicted | B1483: Conflict | C1483: Chouf | D1483: Mount Lebanon | E1483: 23006 | F1483: 0 | H1483: 0.23104263 | K1483: 0
... A1497: Predicted | B1497: Conflict | C1497: El Hermel | D1497: Baalbek-El Hermel | E1497: 54002 | F1497: 0 | H1497: 0.23104263 | K1497: 0
...

Sheet Sheet2
A1: ACS Code
A2: 34381 | B2: 0.16799131
A3: 34286 | B3: 0.28470167
A4: 34386 | B4: 0.15222821
A5: 34287 | B5: 0.23945978
A6: 34133 | B6: 0.12175862
A7: 34188 | B7: 0.58636828
A8: 34341 | B8: 0.52953186
A9: 34263 | B9: 0.2149306
A10: 34356 | B10: 0.17196527
A11: 34229 | B11: 0.159421
A12: 34361 | B12: 0.14761138
A13: 34111 | B13: 0.57111121
... A426: 36114 | B426: 0.12549751

Sheet Prediction Model Variable H
A1: FORECAST.LINEAR(F889,H2:$H$888,$F$2:$F$888) | B1: =_xlfn.FORECAST.LINEAR(G889,I2:$I$888,$G$2:$G$888) -> #DIV/0!

Sheet Sheet1
A1: ACS_CODE | B1: Governorate | C1: District | D1: Cadaster | E1: Syr | F1: PRL | G1: PRS | H1: Leb | I1: Migrant | J1: Total | K1: Column1
A2: 21111 | B2: Mount Lebanon | C2: Baabda | D2: Chiyah | E2: 62902 | F2: 7265 | G2: 1196 | H2: 158073 | I2: 9767 | J2: 239203 | K2: =COUNTIF(DF_Calculation!E:E,Table1[[#This Row],[ACS_CODE]]) -> 1
A3: 54111 | B3: Baalbek-El Hermel | C3: El Hermel | D3: Hermel | E3: 32481 | F3: 0 | G3: 0 | H3: 16704 | I3: 452 | J3: 49637 | K3: =COUNTIF(DF_Calculation!E:E,Table1[[#This Row],[ACS_CODE]]) -> 1
A4: 53231 | B4: Baalbek-El Hermel | C4: Baalbek | D4: Aarsal | E4: 32445 | F4: 0 | G4: 0 | H4: 15105 | I4: 54 | J4: 47604 | K4: =COUNTIF(DF_Calculation!E:E,Table1[[#This Row],[ACS_CODE]]) -> 1
A5: 21177 | B5: Mount Lebanon | C5: Baabda | D5: Bourj El-Brajneh | E5: 27156 | F5: 9302 | G5: 1600 | H5: 90718 | I5: 1865 | J5: 130641 | K5: =COUNTIF(DF_Calculation!E:E,Table1[[#This Row],[ACS_CODE]]) -> 1
A6: 51267 | B6: Bekaa | C6: Zahle | D6: Barr Elias | E6: 26652 | F6: 1626 | G6: 510 | H6: 8362 | I6: 154 | J6: 37304 | K6: =COUNTIF(DF_Calculation!E:E,Table1[[#This Row],[ACS_CODE]]) -> 1
A7: 24111 | B7: Mount Lebanon | C7: Aley | D7: Choueifat El-Aamrousiye | E7: 25798 | F7: 298 | G7: 0 | H7: 70316 | I7: 1760 | J7: 98172 | K7: =COUNTIF(DF_Calculation!E:E,Table1[[#This Row],[ACS_CODE]]) -> 1
A8: 22111 | B8: Mount Lebanon | C8: El Meten | D8: Bourj Hammoud | E8: 19017 | F8: 1038 | G8: 60 | H8: 70331 | I8: 10767 | J8: 101213 | K8: =COUNTIF(DF_Calculation!E:E,Table1[[#This Row],[ACS_CODE]]) -> 1
A9: 53111 | B9: Baalbek-El Hermel | C9: Baalbek | D9: Baalbek | E9: 18910 | F9: 2228 | G9: 1251 | H9: 42977 | I9: 192 | J9: 65558 | K9: =COUNTIF(DF_Calculation!E:E,Table1[[#This Row],[ACS_CODE]]) -> 1
A10: 37231 | B10: North | C10: El Minieh-Dennie | D10: Beddaoui | E10: 18030 | F10: 15044 | G10: 1833 | H10: 28120 | I10: 89 | J10: 63116 | K10: =COUNTIF(DF_Calculation!E:E,Table1[[#This Row],[ACS_CODE]]) -> 1
A11: 51234 | B11: Bekaa | C11: Zahle | D11: Qabb Elias | E11: 15732 | F11: 1626 | G11: 0 | H11: 8868 | I11: 155 | J11: 26381 | K11: =COUNTIF(DF_Calculation!E:E,Table1[[#This Row],[ACS_CODE]]) -> 1
A12: 52277 | B12: Bekaa | C12: West Bekaa | D12: Marj BG | E12: 14463 | F12: 339 | G12: 0 | H12: 3401 | I12: 275 | J12: 18478 | K12: =COUNTIF(DF_Calculation!E:E,Table1[[#This Row],[ACS_CODE]]) -> 1
A13: 35512 | B13: Akkar | C13: Akkar | D13: Aamayer | E13: 13465 | F13: 0 | G13: 0 | H13: 6881 | I13: 63 | J13: 20409 | K13: =COUNTIF(DF_Calculation!E:E,Table1[[#This Row],[ACS_CODE]]) -> 1
... A49: 51221 | B49: Bekaa | C49: Zahle | D49: Taalbaya | E49: 5017 | F49: 1626 | G49: 195 | H49: 10499 | I49: 240 | J49: 17577 | K49: =COUNTIF(DF_Calculation!E:E,Table1[[#This Row],[ACS_CODE]]) -> 1
A50: 35269 | B50: Akkar | C50: Akkar | D50: Qoubber Chamra | E50: 5000 | F50: 0 | G50: 0 | H50: 1377 | J50: 6377 | K50: =COUNTIF(DF_Calculation!E:E,Table1[[#This Row],[ACS_CODE]]) -> 1
A51: 53445 | B51: Baalbek-El Hermel | C51: Baalbek | D51: Nabi Chit | E51: 4973 | F51: 0 | G51: 0 | H51: 5755 | I51: 307 | J51: 11035 | K51: =COUNTIF(DF_Calculation!E:E,Table1[[#This Row],[ACS_CODE]]) -> 1
A52: 35314 | B52: Akkar | C52: Akkar | D52: berqayel | E52: 4825 | F52: 0 | G52: 0 | H52: 7683 | I52: 13 | J52: 12521 | K52: =COUNTIF(DF_Calculation!E:E,Table1[[#This Row],[ACS_CODE]]) -> 1
A53: 22228 | B53: Mount Lebanon | C53: El Meten | D53: Baouchriye | E53: 4766 | F53: 0 | G53: 0 | H53: 60601 | I53: 2406 | J53: 67773 | K53: =COUNTIF(DF_Calculation!E:E,Table1[[#This Row],[ACS_CODE]]) -> 1
A54: 53284 | B54: Baalbek-El Hermel | C54: Baalbek | D54: Youmine | E54: 4587 | F54: 0 | G54: 0 | H54: 3111 | I54: 10 | J54: 7708 | K54: =COUNTIF(DF_Calculation!E:E,Table1[[#This Row],[ACS_CODE]]) -> 1
A55: 53429 | B55: Baalbek-El Hermel | C55: Baalbek | D55: Chmistar | E55: 4437 | F55: 0 | G55: 0 | H55: 6022 | I55: 4 | J55: 10463 | K55: =COUNTIF(DF_Calculation!E:E,Table1[[#This Row],[ACS_CODE]]) -> 1
A56: 24311 | B56: Mount Lebanon | C56: Aley | D56: Aaley | E56: 4362 | F56: 0 | G56: 554 | H56: 21822 | I56: 4115 | J56: 30853 | K56: =COUNTIF(DF_Calculation!E:E,Table1[[#This Row],[ACS_CODE]]) -> 1
A57: 61449 | B57: South | C57: Saida | D57: Sarafand | E57: 4249 | F57: 1221 | G57: 0 | H57: 11602 | I57: 254 | J57: 17326 | K57: =COUNTIF(DF_Calculation!E:E,Table1[[#This Row],[ACS_CODE]]) -> 1
A58: 31151 | B58: North | C58: Tripoli | D58: Trablous El-Qobbe | E58: 4241 | F58: 208 | G58: 0 | H58: 42241 | I58: 63 | J58: 46753 | K58: =COUNTIF(DF_Calculation!E:E,Table1[[#This Row],[ACS_CODE]]) -> 1
A59: 53419 | B59: Baalbek-El Hermel | C59: Baalbek | D59: Haouch Er-Rafqa | E59: 4193 | F59: 0 | G59: 0 | H59: 2738 | I59: 10 | J59: 6941 | K59: =COUNTIF(DF_Calculation!E:E,Table1[[#This Row],[ACS_CODE]]) -> 1
A60: 61311 | B60: South | C60: Saida | D60: Ghaziye | E60: 4121 | F60: 1221 | G60: 89 | H60: 12215 | I60: 178 | J60: 17824 | K60: =COUNTIF(DF_Calculation!E:E,Table1[[#This Row],[ACS_CODE]]) -> 1
A61: 53234 | B61: Baalbek-El Hermel | C61: Baalbek | D61: Laboue | E61: 4091 | F61: 0 | G61: 0 | H61: 5972 | I61: 65 | J61: 10128 | K61: =COUNTIF(DF_Calculation!E:E,Table1[[#This Row],[ACS_CODE]]) -> 1
A62: 35149 | B62: Akkar | C62: Akkar | D62: Deir Dalloum | E62: 4020 | F62: 0 | G62: 0 | H62: 3951 | I62: 3 | J62: 7974 | K62: =COUNTIF(DF_Calculation!E:E,Table1[[#This Row],[ACS_CODE]]) -> 1
... A69: 53425 | B69: Baalbek-El Hermel | C69: Baalbek | D69: Temnine Et-Tahta | E69: 3614 | F69: 0 | G69: 0 | H69: 6221 | I69: 10 | J69: 9845 | K69: =COUNTIF(DF_Calculation!E:E,Table1[[#This Row],[ACS_CODE]]) -> 1
A70: 35467 | B70: Akkar | C70: Akkar | D70: Rihaniyet Aakkar | E70: 3568 | F70: 0 | G70: 0 | H70: 666 | J70: 4234 | K70: =COUNTIF(DF_Calculation!E:E,Table1[[#This Row],[ACS_CODE]]) -> 1
A71: 53123 | B71: Baalbek-El Hermel | C71: Baalbek | D71: Iaat | E71: 3566 | F71: 0 | G71: 0 | H71: 2711 | I71: 15 | J71: 6292 | K71: =COUNTIF(DF_Calculation!E:E,Table1[[#This Row],[ACS_CODE]]) -> 1
A72: 35229 | B72: Akkar | C72: Akkar | D72: Massaaoudiye | E72: 3562 | F72: 0 | G72: 0 | H72: 1234 | I72: 4 | J72: 4800 | K72: =COUNTIF(DF_Calculation!E:E,Table1[[#This Row],[ACS_CODE]]) -> 1
A73: 23271 | B73: Mount Lebanon | C73: Chouf | D73: Jadra | E73: 3508 | F73: 513 | G73: 0 | H73: 706 | I73: 21 | J73: 4748 | K73: =COUNTIF(DF_Calculation!E:E,Table1[[#This Row],[ACS_CODE]]) -> 1
A74: 23111 | B74: Mount Lebanon | C74: Chouf | D74: Damour | E74: 3359 | F74: 513 | G74: 0 | H74: 1441 | I74: 158 | J74: 5471 | K74: =COUNTIF(DF_Calculation!E:E,Table1[[#This Row],[ACS_CODE]]) -> 1
A75: 53437 | B75: Baalbek-El Hermel | C75: Baalbek | D75: Serraaine Et-Tahta | E75: 3290 | F75: 0 | G75: 0 | H75: 5444 | I75: 50 | J75: 8784 | K75: =COUNTIF(DF_Calculation!E:E,Table1[[#This Row],[ACS_CODE]]) -> 1
A76: 10650 | B76: Beirut | C76: Beirut | D76: Achrafieh foncière | E76: 3274 | F76: 0 | G76: 0 | H76: 40263 | I76: 4898 | J76: 48435 | K76: =COUNTIF(DF_Calculation!E:E,Table1[[#This Row],[ACS_CODE]]) -> 1
A77: 52217 | B77: Bekaa | C77: West Bekaa | D77: Kamed El-Laouz | E77: 3106 | F77: 0 | G77: 0 | H77: 4257 | I77: 146 | J77: 7509 | K77: =COUNTIF(DF_Calculation!E:E,Table1[[#This Row],[ACS_CODE]]) -> 1
A78: 51227 | B78: Bekaa | C78: Zahle | D78: Taanayel | E78: 3049 | F78: 0 | G78: 0 | H78: 1222 | I78: 32 | J78: 4303 | K78: =COUNTIF(DF_Calculation!E:E,Table1[[#This Row],[ACS_CODE]]) -> 1
A79: 35261 | B79: Akkar | C79: Akkar | D79: Mqaiteaa | E79: 3033 | F79: 0 | G79: 0 | H79: 2263 | I79: 11 | J79: 5307 | K79: =COUNTIF(DF_Calculation!E:E,Table1[[#This Row],[ACS_CODE]]) -> 1
A80: 33111 | B80: North | C80: Zgharta | D80: Zgharta | E80: 3033 | F80: 0 | G80: 0 | H80: 16652 | I80: 220 | J80: 19905 | K80: =COUNTIF(DF_Calculation!E:E,Table1[[#This Row],[ACS_CODE]]) -> 1
A81: 62128 | B81: South | C81: Sour | D81: Borj Ech-Chemali | E81: 3000 | F81: 9783 | G81: 1892 | H81: 20148 | I81: 607 | J81: 35430 | K81: =COUNTIF(DF_Calculation!E:E,Table1[[#This Row],[ACS_CODE]]) -> 1
...
